Workbook

Sheet Data
A1: Data Source | B1: World Development Indicators
A2: Last Updated Date | B2: 46303
A4: Country Name | B4: Country Code | C4: Indicator Name | D4: Indicator Code | E4: 1960 | F4: 1961 | G4: 1962 | H4: 1963 | I4: 1964 | J4: 1965 | K4: 1966 | L4: 1967 | M4: 1968 | N4: 1969 | O4: 1970 | P4: 1971 | Q4: 1972 | R4: 1973 | S4: 1974 | T4: 1975 | U4: 1976 | V4: 1977 | W4: 1978 | X4: 1979 | Y4: 1980 | Z4: 1981 | AA4: 1982 | AB4: 1983 | AC4: 1984 | AD4: 1985 | AE4: 1986 | AF4: 1987 | AG4: 1988 | AH4: 1989 | AI4: 1990 | AJ4: 1991 | AK4: 1992 | AL4: 1993 | AM4: 1994 | AN4: 1995 | AO4: 1996 | AP4: 1997 | AQ4: 1998 | AR4: 1999 | AS4: 2000 | AT4: 2001 | AU4: 2002 | AV4: 2003 | AW4: 2004 | AX4: 2005 | AY4: 2006 | AZ4: 2007 | BA4: 2008 | BB4: 2009 | BC4: 2010 | BD4: 2011 | BE4: 2012 | BF4: 2013 | BG4: 2014 | BH4: 2015 | BI4: 2016 | BJ4: 2017 | BK4: 2018 | BL4: 2019 | BM4: 2020 | BN4: 2021 | BO4: 2022 | BP4: 2023 | BQ4: 2024 | BR4: 2025
A5: Aruba | B5: ABW | C5: Individuals using the Internet (% of population) | D5: IT.NET.USER.ZS | AI5: 0 | AO5: 2.77 | AR5: 4.51 | AS5: 15.442823 | AT5: 17.1 | AU5: 18.8 | AV5: 20.8 | AW5: 23 | AX5: 25.4 | AY5: 28 | AZ5: 30.9 | BA5: 52 | BB5: 58 | BC5: 62 | BD5: 69 | BE5: 74 | BF5: 78.9 | BG5: 83.78 | BH5: 88.661227 | BI5: 93.542454 | BJ5: 97.17
A6: Africa Eastern and Southern | B6: AFE | C6: Individuals using the Internet (% of population) | D6: IT.NET.USER.ZS | AX6: 1.8 | AY6: 1.9 | AZ6: 2.7 | BA6: 3 | BB6: 3.5 | BC6: 5.3 | BD6: 6.8 | BE6: 8.4 | BF6: 10 | BG6: 12.1 | BH6: 14.3 | BI6: 16.3 | BJ6: 17.3 | BK6: 19.6 | BL6: 21.6 | BM6: 23.5 | BN6: 25 | BO6: 26.8 | BP6: 27.8 | BQ6: 28.8 | BR6: 30.4
A7: Afghanistan | B7: AFG | C7: Individuals using the Internet (% of population) | D7: IT.NET.USER.ZS | AI7: 0 | AT7: 0.0047225682 | AU7: 0.0045613952 | AV7: 0.087891253 | AW7: 0.10580903 | AX7: 1.2241481 | AY7: 2.1071236 | AZ7: 1.9 | BA7: 1.84 | BB7: 3.55 | BC7: 4 | BD7: 5 | BE7: 5.4545002 | BF7: 5.9000001 | BG7: 7 | BH7: 8.2600002 | BI7: 11 | BJ7: 13.5 | BK7: 16.799999 | BL7: 17.6 | BM7: 17.0485 | BN7: 16.514299 | BO7: 15.8663 | BP7: 15.9284 | BQ7: 16.094999
A8: Africa Western and Central | B8: AFW | C8: Individuals using the Internet (% of population) | D8: IT.NET.USER.ZS | AX8: 2.3 | AY8: 3.4 | AZ8: 4.3 | BA8: 5 | BB8: 5.8 | BC8: 7.3 | BD8: 8.7 | BE8: 10.3 | BF8: 12.6 | BG8: 15 | BH8: 18.6 | BI8: 20.9 | BJ8: 23.8 | BK8: 25.7 | BL8: 28.5 | BM8: 31.5 | BN8: 34.7 | BO8: 37.5 | BP8: 38.5 | BQ8: 40 | BR8: 42.4
A9: Angola | B9: AGO | C9: Individuals using the Internet (% of population) | D9: IT.NET.USER.ZS | AI9: 0 | AO9: 0.000776 | AP9: 0.00567 | AQ9: 0.0185 | AR9: 0.072 | AS9: 0.10504556 | AT9: 0.13601387 | AU9: 0.27037675 | AV9: 0.37068207 | AW9: 0.46481462 | AX9: 1.1434 | AY9: 1.5 | AZ9: 1.7 | BA9: 1.9 | BB9: 2.3 | BC9: 2.8 | BD9: 4.6999998 | BE9: 7.6999998 | BF9: 13 | BG9: 21.362341 | BH9: 22 | BI9: 23.200001 | BJ9: 26 | BK9: 29 | BL9: 32.129398 | BM9: 33.3209 | BN9: 34.556499 | BO9: 35.838001 | BP9: 37.885899 | BQ9: 40.7048
A10: Albania | B10: ALB | C10: Individuals using the Internet (% of population) | D10: IT.NET.USER.ZS | AI10: 0 | AN10: 0.0112 | AO10: 0.0322 | AP10: 0.0486 | AQ10: 0.065 | AR10: 0.0814 | AS10: 0.11409735 | AT10: 0.32579838 | AU10: 0.39008127 | AV10: 0.97190042 | AW10: 2.4203878 | AX10: 6.0438909 | AY10: 9.6099997 | AZ10: 15.0361 | BA10: 23.86 | BB10: 41.2 | BC10: 45 | BD10: 47 | BE10: 49.400002 | BF10: 51.799999 | BG10: 54.299999 | BH10: 56.900002 | BI10: 59.599998 | BJ10: 62.400002 | BK10: 65.400002 | BL10: 68.550391 | BM10: 72.237677 | BN10: 79.323718 | BO10: 82.613675 | BP10: 83.135592 | BQ10: 85.863899
A11: Andorra | B11: AND | C11: Individuals using the Internet (% of population) | D11: IT.NET.USER.ZS | AI11: 0 | AO11: 1.53 | AP11: 3.05 | AQ11: 6.89 | AR11: 7.64 | AS11: 10.538836 | AU11: 11.260469 | AV11: 13.546413 | AW11: 26.837954 | AX11: 37.605766 | AY11: 48.936847 | AZ11: 70.87 | BA11: 70.04 | BB11: 78.53 | BC11: 81 | BD11: 81 | BE11: 82.699997 | BF11: 84.400002 | BG11: 86.099998 | BH11: 87.900002 | BI11: 89.699997 | BJ11: 91.567467 | BK11: 93.5 | BL11: 90.718697 | BM11: 93.205704 | BN11: 93.897499 | BO11: 94.051697 | BP11: 94.214996 | BQ11: 94.397598
A12: Arab World | B12: ARB | C12: Individuals using the Internet (% of population) | D12: IT.NET.USER.ZS
A13: United Arab Emirates | B13: ARE | C13: Individuals using the Internet (% of population) | D13: IT.NET.USER.ZS | AI13: 0 | AN13: 0.103 | AO13: 0.375 | AP13: 3.3 | AQ13: 6.91 | AR13: 14.9 | AS13: 23.625301 | AT13: 26.271754 | AU13: 28.316485 | AV13: 29.477953 | AW13: 30.131296 | AX13: 40 | AY13: 52 | AZ13: 61 | BA13: 63 | BB13: 64 | BC13: 68 | BD13: 78 | BE13: 84.999992 | BF13: 88 | BG13: 90.400011 | BH13: 90.5 | BI13: 90.600007 | BJ13: 94.819923 | BK13: 98.450002 | BL13: 99.149998 | BM13: 100 | BN13: 100 | BO13: 100 | BP13: 100 | BQ13: 100
A14: Argentina | B14: ARG | C14: Individuals using the Internet (% of population) | D14: IT.NET.USER.ZS | AI14: 0 | AK14: 0.00299 | AL14: 0.0295 | AM14: 0.0437 | AN14: 0.0863 | AO14: 0.142 | AP14: 0.28 | AQ14: 0.831 | AR14: 3.28 | AS14: 7.0386831 | AT14: 9.7808073 | AU14: 10.882124 | AV14: 11.913697 | AW14: 16.036684 | AX14: 17.720583 | AY14: 20.927202 | AZ14: 25.946633 | BA14: 28.112623 | BB14: 34 | BC14: 45 | BD14: 51 | BE14: 55.799999 | BF14: 59.900002 | BG14: 64.699997 | BH14: 68.043064 | BI14: 70.968981 | BJ14: 74.294907 | BK14: 77.7 | BL14: 79.946952 | BM14: 85.514386 | BN14: 87.150707 | BO14: 88.375357 | BP14: 89.228972 | BQ14: 89.667152
A15: Armenia | B15: ARM | C15: Individuals using the Internet (% of population) | D15: IT.NET.USER.ZS | AI15: 0 | AM15: 0.00912 | AN15: 0.0527 | AO15: 0.0946 | AP15: 0.112 | AQ15: 0.129 | AR15: 0.971 | AS15: 1.30047 | AT15: 1.6310947 | AU15: 1.960405 | AV15: 4.5752172 | AW15: 4.8990086 | AX15: 5.2529998 | AY15: 5.6318002 | AZ15: 6.0212998 | BA15: 6.21 | BB15: 15.3 | BC15: 25 | BD15: 32 | BE15: 37.5 | BF15: 41.9 | BG15: 54.622806 | BH15: 59.100834 | BI15: 64.34603 | BJ15: 64.744884 | BK15: 68.245052 | BL15: 66.54395 | BM15: 76.507701 | BN15: 78.612258 | BO15: 77.027675 | BP15: 79.99663 | BQ15: 81.339302
A16: American Samoa | B16: ASM | C16: Individuals using the Internet (% of population) | D16: IT.NET.USER.ZS | AI16: 0
A17: Antigua and Barbuda | B17: ATG | C17: Individuals using the Internet (% of population) | D17: IT.NET.USER.ZS | AI17: 0 | AN17: 2.2 | AO17: 2.86 | AP17: 3.48 | AQ17: 4.07 | AR17: 5.3 | AS17: 6.4822257 | AT17: 8.8992855 | AU17: 12.5 | AV17: 17.228649 | AW17: 24.266544 | AX17: 27 | AY17: 30 | AZ17: 34 | BA17: 38 | BB17: 42 | BC17: 47 | BD17: 52 | BE17: 58 | BF17: 63.400002 | BG17: 67.779999 | BH17: 70 | BI17: 70.271599 | BJ17: 70.544197 | BK17: 70.817902 | BL17: 71.092598 | BM17: 71.368401 | BN17: 71.645302 | BO17: 71.923302 | BP17: 72.1241 | BQ17: 72.7304
A18: Australia | B18: AUS | C18: Individuals using the Internet (% of population) | D18: IT.NET.USER.ZS | AI18: 0.585 | AJ18: 1.1 | AK18: 1.77 | AL18: 1.97 | AM18: 2.23 | AN18: 2.76 | AO18: 3.28 | AP18: 16.4 | AQ18: 30.8 | AR18: 40.8 | AS18: 46.756116 | AT18: 52.689266 | AX18: 63 | AY18: 66 | AZ18: 69.45 | BA18: 71.67 | BB18: 74.25 | BC18: 76 | BD18: 79.487698 | BE18: 79 | BF18: 83.453497 | BG18: 84 | BH18: 84.560515 | BI18: 86.540001 | BJ18: 86.545049 | BK18: 90.008202 | BL18: 93.609901 | BM18: 94.693497 | BN18: 96.972198 | BO18: 96.1194 | BP18: 96.116096 | BQ18: 96.131401
A19: Austria | B19: AUT | C19: Individuals using the Internet (% of population) | D19: IT.NET.USER.ZS | AI19: 0.13 | AJ19: 0.259 | AK19: 0.643 | AL19: 0.765 | AM19: 1.39 | AN19: 1.89 | AO19: 6.91 | AP19: 9.53 | AQ19: 15.4 | AR19: 23 | AS19: 33.730133 | AT19: 39.18545 | AU19: 36.56 | AV19: 42.7 | AW19: 54.28 | AX19: 58 | AY19: 63.6 | AZ19: 69.37 | BA19: 72.87 | BB19: 73.45 | BC19: 75.17 | BD19: 78.739993 | BE19: 80.029994 | BF19: 80.6188 | BG19: 80.995825 | BH19: 83.940142 | BI19: 84.323743 | BJ19: 87.935587 | BK19: 87.479137 | BL19: 87.752205 | BM19: 87.529428 | BN19: 92.529151 | BO19: 93.614091 | BP19: 95.334671 | BQ19: 94.919749 | BR19: 91.925734
A20: Azerbaijan | B20: AZE | C20: Individuals using the Internet (% of population) | D20: IT.NET.USER.ZS | AI20: 0 | AM20: 0.00143 | AN20: 0.00206 | AO20: 0.00635 | AP20: 0.0252 | AQ20: 0.0375 | AR20: 0.0992 | AS20: 0.14775758 | AT20: 0.30556464 | AU20: 4.9997137 | AX20: 8.0304003 | AY20: 11.9922 | AZ20: 14.54 | BA20: 17.08 | BB20: 27.4 | BC20: 46 | BD20: 50 | BE20: 54.200001 | BF20: 73.000001 | BG20: 75.000016 | BH20: 77 | BI20: 78.2 | BJ20: 79 | BK20: 79.799995 | BL20: 81.099999 | BM20: 84.599996 | BN20: 85.99999 | BO20: 88 | BP20: 89 | BQ20: 90.439796 | BR20: 90.800002
A21: Burundi | B21: BDI | C21: Individuals using the Internet (% of population) | D21: IT.NET.USER.ZS | AI21: 0 | AJ21: 0 | AK21: 0 | AL21: 0 | AM21: 0 | AN21: 0 | AO21: 0.000804 | AP21: 0.00798 | AQ21: 0.0158 | AR21: 0.0392 | AS21: 0.077248447 | AT21: 0.10600125 | AU21: 0.11822841 | AV21: 0.2012732 | AW21: 0.34906046 | AX21: 0.54210001 | AY21: 0.65759999 | AZ21: 0.7 | BA21: 0.81 | BB21: 0.89999998 | BC21: 1 | BD21: 1.11 | BE21: 1.22 | BF21: 1.2642181 | BG21: 1.0423921 | BH21: 2 | BI21: 2.2 | BJ21: 2.6607485 | BK21: 4.0194998 | BL21: 6.0721998 | BM21: 6.4301 | BN21: 6.7779999 | BO21: 7.1448002 | BP21: 7.1722999 | BQ21: 8.5959997
A22: Belgium | B22: BEL | C22: Individuals using the Internet (% of population) | D22: IT.NET.USER.ZS | AI22: 0.00101 | AJ22: 0.0201 | AK22: 0.1 | AL22: 0.199 | AM22: 0.696 | AN22: 0.992 | AO22: 2.97 | AP22: 4.94 | AQ22: 7.89 | AR22: 13.8 | AS22: 29.431692 | AT22: 31.288396 | AU22: 46.33 | AV22: 49.97 | AW22: 53.86 | AX22: 55.82 | AY22: 61.98187 | AZ22: 66.76042 | BA22: 68.857322 | BB22: 74.544146 | BC22: 77.639786 | BD22: 81.609996 | BE22: 80.719991 | BF22: 82.1702 | BG22: 85.001238 | BH22: 85.052942 | BI22: 86.516477 | BJ22: 87.679681 | BK22: 88.647343 | BL22: 90.275428 | BM22: 91.526416 | BN22: 92.788676 | BO22: 94.007831 | BP22: 94.626251 | BQ22: 95.775791
A23: Benin | B23: BEN | C23: Individuals using the Internet (% of population) | D23: IT.NET.USER.ZS | AI23: 0 | AO23: 0.00169 | AP23: 0.0246 | AQ23: 0.0479 | AR23: 0.155 | AS23: 0.22524785 | AT23: 0.36341789 | AU23: 0.7029456 | AV23: 0.95132711 | AW23: 1.182541 | AX23: 1.271 | AY23: 1.5379 | AZ23: 1.79 | BA23: 1.85 | BB23: 2.24 | BC23: 3.13 | BD23: 4.1483231 | BE23: 4.5 | BF23: 4.9000001 | BG23: 6 | BH23: 11.255 | BI23: 14.5 | BJ23: 18.7 | BK23: 19 | BL23: 20.500999 | BM23: 22.1206 | BN23: 28.2047 | BO23: 30.5373 | BP23: 32.394001 | BQ23: 33.983799
A24: Burkina Faso | B24: BFA | C24: Individuals using the Internet (% of population) | D24: IT.NET.USER.ZS | AI24: 0 | AO24: 0.000961 | AP24: 0.0187 | AQ24: 0.0454 | AR24: 0.0618 | AS24: 0.077080169 | AT24: 0.15773246 | AU24: 0.2009926 | AV24: 0.3734403 | AW24: 0.40029529 | AX24: 0.46990001 | AY24: 0.63270003 | AZ24: 0.75 | BA24: 0.92000002 | BB24: 1.13 | BC24: 2.4000001 | BD24: 3 | BE24: 3.7249999 | BF24: 5 | BG24: 6 | BH24: 6.5457001 | BI24: 7.1409998 | BJ24: 7.7904 | BK24: 8.4989004 | BL24: 9.271806 | BM24: 12.9732 | BN24: 18.152201 | BO24: 25.3988 | BP24: 25.3612 | BQ24: 28.252701
A25: Bangladesh | B25: BGD | C25: Individuals using the Internet (% of population) | D25: IT.NET.USER.ZS | AI25: 0 | AP25: 0.000751 | AQ25: 0.00368 | AR25: 0.0362 | AS25: 0.071039423 | AT25: 0.12980797 | AU25: 0.13992029 | AV25: 0.16387767 | AW25: 0.19903633 | AX25: 0.24160001 | AY25: 1 | AZ25: 1.8 | BA25: 2.5 | BB25: 3.0999999 | BC25: 3.7 | BD25: 4.5 | BE25: 5 | BF25: 6.63 | BG25: 9.0529003 | BH25: 12.3688 | BI25: 16.899099 | BJ25: 21.5 | BK25: 25.5651 | BL25: 30.383101 | BM25: 36.1091 | BN25: 38.917445 | BO25: 41.616501 | BP25: 44.502742 | BQ25: 53.421713
A26: Bulgaria | B26: BGR | C26: Individuals using the Internet (% of population) | D26: IT.NET.USER.ZS | AI26: 0 | AL26: 0.00234 | AM26: 0.0195 | AN26: 0.12 | AO26: 0.725 | AP26: 1.22 | AQ26: 1.84 | AR26: 2.91 | AS26: 5.3709235 | AT26: 7.6122977 | AU26: 9.08 | AV26: 12.04 | AW26: 18.13 | AX26: 19.97 | AY26: 27.09 | AZ26: 33.64 | BA26: 39.67 | BB26: 45 | BC26: 46.23 | BD26: 47.979993 | BE26: 51.899988 | BF26: 53.0615 | BG26: 55.490377 | BH26: 56.656252 | BI26: 59.825548 | BJ26: 63.410101 | BK26: 64.782011 | BL26: 67.946981 | BM26: 70.162484 | BN26: 75.271446 | BO26: 79.126863 | BP26: 80.389565 | BQ26: 82.438955
A27: Bahrain | B27: BHR | C27: Individuals using the Internet (% of population) | D27: IT.NET.USER.ZS | AI27: 0 | AN27: 0.346 | AO27: 0.843 | AP27: 1.65 | AQ27: 3.22 | AR27: 4.72 | AS27: 6.1537325 | AT27: 15.038634 | AU27: 18.050721 | AV27: 21.554945 | AW27: 21.458681 | AX27: 21.303699 | AY27: 28.243999 | AZ27: 32.91 | BA27: 51.95 | BB27: 53 | BC27: 55 | BD27: 76.999967 | BE27: 88 | BF27: 90.00004 | BG27: 90.503133 | BH27: 93.478301 | BI27: 97.999981 | BJ27: 95.878136 | BK27: 98.644673 | BL27: 99.701504 | BM27: 99.671032 | BN27: 100 | BO27: 100 | BP27: 100 | BQ27: 100
A28: Bahamas, The | B28: BHS | C28: Individuals using the Internet (% of population) | D28: IT.NET.USER.ZS | AI28: 0 | AN28: 0.96 | AO28: 1.75 | AP28: 1.36 | AQ28: 2.34 | AR28: 3.76 | AS28: 8 | AT28: 11.8 | AU28: 18 | AV28: 20 | AW28: 22 | AX28: 25 | AY28: 26 | AZ28: 27 | BA28: 31.54 | BB28: 33.88 | BC28: 43 | BD28: 65 | BE28: 71.748199 | BF28: 72 | BG28: 76.919998 | BH28: 78 | BI28: 80 | BJ28: 80.599998 | BK28: 83 | BL28: 90.693298 | BM28: 92.443703 | BN28: 92.3498 | BO28: 92.255997 | BP28: 92.387299 | BQ28: 92.472702
A29: Bosnia and Herzegovina | B29: BIH | C29: Individuals using the Internet (% of population) | D29: IT.NET.USER.ZS | AI29: 0 | AO29: 0.0151 | AP29: 0.0594 | AQ29: 0.144 | AR29: 0.194 | AS29: 1.0829607 | AT29: 1.200527 | AU29: 2.6482679 | AV29: 3.9650368 | AW29: 15.468972 | AX29: 21.326701 | AY29: 25.122386 | AZ29: 27.92 | BA29: 34.66 | BB29: 37.74 | BC29: 42.75 | BD29: 43.887699 | BE29: 45.064499 | BF29: 48.521301 | BG29: 49.917702 | BH29: 52.599998 | BI29: 60.256535 | BJ29: 64.892021 | BK29: 70.120135 | BL29: 69.946348 | BM29: 73.211753 | BN29: 75.676201 | BO29: 78.845537 | BP29: 83.377154 | BQ29: 86.100911
A30: Belarus | B30: BLR | C30: Individuals using the Internet (% of population) | D30: IT.NET.USER.ZS | AI30: 0 | AM30: 0.000486 | AN30: 0.00292 | AO30: 0.0293 | AP30: 0.049 | AQ30: 0.0739 | AR30: 0.495 | AS30: 1.8603981 | AT30: 4.300616 | AU30: 8.9509713 | AY30: 16.2 | AZ30: 19.7 | BA30: 23 | BB30: 27.43 | BC30: 31.8 | BD30: 39.648896 | BE30: 46.91 | BF30: 54.17 | BG30: 59.016319 | BH30: 62.230361 | BI30: 71.113046 | BJ30: 74.436445 | BK30: 79.129887 | BL30: 82.789152 | BM30: 85.087912 | BN30: 86.888412 | BO30: 89.507331 | BP30: 91.5125 | BQ30: 94.261821
A31: Belize | B31: BLZ | C31: Individuals using the Internet (% of population) | D31: IT.NET.USER.ZS | AI31: 0 | AN31: 0.0454 | AO31: 0.883 | AP31: 1.29 | AQ31: 2.09 | AR31: 4.08 | AS31: 5.9638353 | AU31: 5.6842512 | AW31: 9.8 | AX31: 17 | AY31: 24 | AZ31: 24.6 | BA31: 26.299999 | BB31: 27.200001 | BC31: 28.2 | BD31: 30.700001 | BE31: 31 | BF31: 33.599998 | BG31: 38.700001 | BH31: 41.59 | BI31: 44.575699 | BJ31: 48.877102 | BK31: 53.593601 | BL31: 58.765202 | BM31: 64.435898 | BN31: 70.653702 | BO31: 69.983299 | BP31: 70.187202 | BQ31: 80.005823
A32: Bermuda | B32: BMU | C32: Individuals using the Internet (% of population) | D32: IT.NET.USER.ZS | AI32: 0 | AN32: 6.84 | AO32: 16.2 | AP32: 24.2 | AQ32: 32.1 | AR32: 39.9 | AS32: 42.94986 | AT32: 47.5097 | AU32: 52.031597 | AV32: 56.522012 | AW32: 60.990867 | AX32: 65.447066 | AY32: 69.899655 | AZ32: 74.350594 | BA32: 82.3 | BB32: 83.25 | BC32: 84.21 | BD32: 88.336 | BE32: 91.299305 | BF32: 95.3 | BG32: 96.8 | BH32: 98.32361 | BI32: 98 | BJ32: 98.37
A33: Bolivia | B33: BOL | C33: Individuals using the Internet (% of population) | D33: IT.NET.USER.ZS | AI33: 0 | AN33: 0.0668 | AO33: 0.196 | AP33: 0.448 | AQ33: 0.626 | AR33: 0.982 | AS33: 1.4427636 | AT33: 2.1204625 | AU33: 3.1171929 | AV33: 3.5085964 | AW33: 4.4399246 | AX33: 5.227584 | AY33: 6.2006713 | AZ33: 10.4992 | BA33: 12.5 | BB33: 16.799999 | BC33: 22.4 | BD33: 30 | BE33: 35.34 | BF33: 36.99 | BG33: 34.60162 | BH33: 37.486818 | BI33: 39.697498 | BJ33: 43.832298 | BK33: 44.286142 | BL33: 47.474819 | BM33: 59.940102 | BN33: 65.977379 | BO33: 72.622704 | BP33: 77.3004 | BQ33: 79.704697
A34: Brazil | B34: BRA | C34: Individuals using the Internet (% of population) | D34: IT.NET.USER.ZS | AI34: 0 | AJ34: 0.00329 | AK34: 0.0129 | AL34: 0.0255 | AM34: 0.0377 | AN34: 0.105 | AO34: 0.451 | AP34: 0.786 | AQ34: 1.48 | AR34: 2.04 | AS34: 2.8706852 | AT34: 4.5284949 | AU34: 9.1494251 | AV34: 13.207586 | AW34: 19.073672 | AX34: 21.022747 | AY34: 28.1784 | AZ34: 30.879999 | BA34: 33.83 | BB34: 39.22 | BC34: 40.65 | BD34: 45.69 | BE34: 48.56 | BF34: 51.04 | BG34: 54.551002 | BH34: 58.327952 | BI34: 60.87254 | BJ34: 67.471285 | BK34: 70.434283 | BL34: 73.91244 | BM34: 81.342694 | BN34: 80.689893 | BO34: 80.527751 | BP34: 84.150602 | BQ34: 84.463472
A35: Barbados | B35: BRB | C35: Individuals using the Internet (% of population) | D35: IT.NET.USER.ZS | AI35: 0 | AN35: 0.00775 | AO35: 0.389 | AP35: 0.783 | AQ35: 1.97 | AR35: 2.38 | AS35: 3.9736784 | AT35: 11.93645 | AU35: 27.836322 | AV35: 39.689627 | AW35: 49.8 | AX35: 52.5 | AY35: 55.299999 | AZ35: 58.200001 | BA35: 61.400002 | BB35: 64.699997 | BC35: 65.099998 | BD35: 66.5 | BE35: 71.199997 | BF35: 71.800003 | BG35: 71.924599 | BH35: 72.0494 | BI35: 71.572998 | BJ35: 71.148499 | BK35: 70.726501 | BL35: 70.307098 | BM35: 69.890099 | BN35: 69.475601 | BO35: 69.063599 | BP35: 69.675102 | BQ35: 70.3647
A36: Brunei Darussalam | B36: BRN | C36: Individuals using the Internet (% of population) | D36: IT.NET.USER.ZS | AI36: 0 | AN36: 1.02 | AO36: 3.3 | AP36: 4.83 | AQ36: 6.28 | AR36: 7.67 | AS36: 8.9962845 | AT36: 12.917769 | AU36: 15.32988 | AV36: 19.595003 | AW36: 29.715604 | AX36: 36.466392 | AY36: 42.186349 | AZ36: 44.68 | BA36: 46 | BB36: 49 | BC36: 53 | BD36: 56 | BE36: 60.273102 | BF36: 64.5 | BG36: 68.769997 | BH36: 71.199997 | BI36: 90 | BJ36: 94.866699 | BK36: 95 | BL36: 95 | BM36: 96.305496 | BN36: 97.628799 | BO36: 98.970426 | BP36: 98.970398 | BQ36: 96.298288
A37: Bhutan | B37: BTN | C37: Individuals using the Internet (% of population) | D37: IT.NET.USER.ZS | AI37: 0 | AR37: 0.138 | AS37: 0.40094445 | AT37: 0.86462856 | AU37: 1.6758026 | AV37: 2.4369124 | AW37: 3.1569842 | AX37: 3.8471 | AY37: 4.5183001 | AZ37: 5.92 | BA37: 6.55 | BB37: 7.17 | BC37: 13.6 | BD37: 14.4 | BE37: 15.6 | BF37: 22.4 | BG37: 30.299999 | BH37: 39.799999 | BI37: 46.503201 | BJ37: 54.335499 | BK37: 63.486801 | BL37: 74.179398 | BM37: 76.8508 | BN37: 85.636884 | BO37: 88.356201 | BP37: 90.0214 | BQ37: 91.277397
A38: Botswana | B38: BWA | C38: Individuals using the Internet (% of population) | D38: IT.NET.USER.ZS | AI38: 0 | AJ38: 0 | AN38: 0.0645 | AO38: 0.157 | AP38: 0.308 | AQ38: 0.602 | AR38: 1.12 | AS38: 2.9026666 | AT38: 3.4308868 | AU38: 3.3859224 | AV38: 3.3451902 | AW38: 3.3048893 | AX38: 3.2625999 | AY38: 4.289933 | AZ38: 5.28 | BA38: 6.25 | BB38: 6.1500001 | BC38: 6 | BD38: 9 | BE38: 16 | BF38: 30 | BG38: 36.744747 | BH38: 38.893799 | BI38: 41.168598 | BJ38: 43.576401 | BK38: 46.125099 | BL38: 48.8228 | BM38: 51.6782 | BN38: 54.700699 | BO38: 57.9 | BQ38: 57.4595
A39: Central African Republic | B39: CAF | C39: Individuals using the Internet (% of population) | D39: IT.NET.USER.ZS | AI39: 0 | AO39: 0.00585 | AP39: 0.0143 | AQ39: 0.0279 | AR39: 0.0409 | AS39: 0.053394174 | AT39: 0.078543428 | AU39: 0.12853712 | AV39: 0.15156334 | AW39: 0.2234014 | AX39: 0.26820001 | AY39: 0.31119999 | AZ39: 0.37581596 | BA39: 1 | BB39: 1.8 | BC39: 2 | BD39: 2.2 | BE39: 2.4000001 | BF39: 2.5 | BG39: 2.7 | BH39: 2.9000001 | BI39: 3.0999999 | BJ39: 4 | BK39: 5.0999999 | BL39: 7.5092001 | BO39: 13.7536 | BP39: 13.8417 | BQ39: 13.7825
A40: Canada | B40: CAN | C40: Individuals using the Internet (% of population) | D40: IT.NET.USER.ZS | AI40: 0.361 | AJ40: 0.57 | AK40: 0.916 | AL40: 1.18 | AM40: 2.38 | AN40: 4.16 | AO40: 6.76 | AP40: 15.1 | AQ40: 24.9 | AR40: 36.2 | AS40: 51.3 | AT40: 60.2 | AU40: 61.593299 | AV40: 64.2 | AW40: 65.955963 | AX40: 71.66 | AY40: 72.400002 | AZ40: 73.2 | BA40: 76.699997 | BB40: 80.3 | BC40: 80.3 | BD40: 83 | BE40: 83 | BF40: 85.800003 | BG40: 87.120003 | BH40: 90 | BI40: 91.160004 | BJ40: 92.701401 | BK40: 94.64 | BL40: 91.912903 | BM40: 92.3 | BN40: 93.937103 | BO40: 94 | BP40: 94.145302 | BQ40: 94.353302
A41: Central Europe and the Baltics | B41: CEB | C41: Individuals using the Internet (% of population) | D41: IT.NET.USER.ZS
...

Sheet Metadata - Countries
A1: Country Code | B1: Region | C1: IncomeGroup | D1: SpecialNotes | E1: TableName
A2: ABW | B2: Latin America & Caribbean | C2: High income | E2: Aruba
A3: AFE | D3: 26 countries, stretching from the Red Sea in the North to the Cape of Good Hope in the South (https://www.worldbank.org/en/region/afr/eastern-and-southern-africa) | E3: Africa Eastern and Southern
A4: AFG | B4: Middle East & North Africa | C4: Low income | D4: The reporting period for national accounts data is designated as either calendar year basis (CY) or fiscal year basis (FY). For this country, it is fiscal year-based (fiscal year-end: March 20). Also, an estimate (PA.NUS.ATLS) of the exchange rate covers the same period and thus differs from the official exchange rate (CY). In addition, the World Bank systematically assesses the appropriateness of official exchange rates as conversion factors. In this country, multiple or dual exchange rate activity exists and must be accounted for appropriately in underlying statistics. An alternative estimate (“alternative conversion factor” - PA.NUS.ATLS) is thus calculated as a weighted average of the different exchange rates in use in the country. Doing so better reflects economic reality and leads to more accurate cross-country comparisons and country classifications by income level. For this country, this applies to the period 1960-2006. Alternative conversion factors are used in the Atlas methodology and elsewhere in World Development Indicators as single-year conversion factors. | E4: Afghanistan
A5: AFW | D5: 22 countries, stretching from the westernmost point of Africa, across the equator, and partly along the Atlantic Ocean till the Republic of Congo in the South (https://www.worldbank.org/en/region/afr/western-and-central-africa) | E5: Africa Western and Central
A6: AGO | B6: Sub-Saharan Africa | C6: Lower middle income | D6: The World Bank systematically assesses the appropriateness of official exchange rates as conversion factors. In this country, multiple or dual exchange rate activity exists and must be accounted for appropriately in underlying statistics. An alternative estimate (“alternative conversion factor” - PA.NUS.ATLS) is thus calculated as a weighted average of the different exchange rates in use in the country. Doing so better reflects economic reality and leads to more accurate cross-country comparisons and country classifications by income level. For this country, this applies to the period 1994-2025. Alternative conversion factors are used in the Atlas methodology and elsewhere in World Development Indicators as single-year conversion factors. | E6: Angola
A7: ALB | B7: Europe & Central Asia | C7: Upper middle income | E7: Albania
A8: AND | B8: Europe & Central Asia | C8: High income | E8: Andorra
A9: ARB | D9: Arab World aggregate. Arab World is composed of members of the League of Arab States. | E9: Arab World
A10: ARE | B10: Middle East & North Africa | C10: High income | E10: United Arab Emirates
A11: ARG | B11: Latin America & Caribbean | C11: Upper middle income | D11: Due to the limitations of the Atlas method in classifying countries experiencing persistent high inflation, this economy remains classified as upper-middle-income. The World Bank systematically assesses the appropriateness of official exchange rates as conversion factors. In this country, multiple or dual exchange rate activity exists and must be accounted for appropriately in underlying statistics. An alternative estimate (“alternative conversion factor” - PA.NUS.ATLS) is thus calculated as a weighted average of the different exchange rates in use in the country. Doing so better reflects economic reality and leads to more accurate cross-country comparisons and country classifications by income level. For this country, this applies to the period 1971-2018. Alternative conversion factors are used in the Atlas methodology and elsewhere in World Development Indicators as single-year conversion factors. | E11: Argentina
A12: ARM | B12: Europe & Central Asia | C12: Upper middle income | E12: Armenia
A13: ASM | B13: East Asia & Pacific | C13: High income | E13: American Samoa
A14: ATG | B14: Latin America & Caribbean | C14: High income | E14: Antigua and Barbuda
A15: AUS | B15: East Asia & Pacific | C15: High income | D15: The reporting period for national accounts data is designated as either calendar year basis (CY) or fiscal year basis (FY). For this country, it is fiscal year-based (fiscal year-end: June 30). Also, an estimate (PA.NUS.ATLS) of the exchange rate covers the same period and thus differs from the official exchange rate (CY). | E15: Australia
A16: AUT | B16: Europe & Central Asia | C16: High income | D16: A simple multiplier is used to convert the national currencies of EMU members to euros. The following irrevocable euro conversion rate was adopted by the EU Council on January 1, 1999: 1 euro = 13.7603 Austrian schilling. Please note that historical data before 1999 are not actual euros and are not comparable or suitable for aggregation across countries. | E16: Austria
A17: AZE | B17: Europe & Central Asia | C17: Upper middle income | E17: Azerbaijan
A18: BDI | B18: Sub-Saharan Africa | C18: Low income | D18: The World Bank systematically assesses the appropriateness of official exchange rates as conversion factors. In this country, multiple or dual exchange rate activity exists and must be accounted for appropriately in underlying statistics. An alternative estimate (“alternative conversion factor” - PA.NUS.ATLS) is thus calculated as a weighted average of the different exchange rates in use in the country. Doing so better reflects economic reality and leads to more accurate cross-country comparisons and country classifications by income level. For this country, this applies to the period 1983-2025. Alternative conversion factors are used in the Atlas methodology and elsewhere in World Development Indicators as single-year conversion factors. | E18: Burundi
A19: BEL | B19: Europe & Central Asia | C19: High income | D19: A simple multiplier is used to convert the national currencies of EMU members to euros. The following irrevocable euro conversion rate was adopted by the EU Council on January 1, 1999: 1 euro = 40.3399 Belgian franc. Please note that historical data before 1999 are not actual euros and are not comparable or suitable for aggregation across countries. | E19: Belgium
A20: BEN | B20: Sub-Saharan Africa | C20: Lower middle income | E20: Benin
A21: BFA | B21: Sub-Saharan Africa | C21: Low income | E21: Burkina Faso
A22: BGD | B22: South Asia | C22: Lower middle income | D22: The reporting period for national accounts data is designated as either calendar year basis (CY) or fiscal year basis (FY). For this country, it is fiscal year-based (fiscal year-end: June 30). Also, an estimate (PA.NUS.ATLS) of the exchange rate covers the same period and thus differs from the official exchange rate (CY). | E22: Bangladesh
A23: BGR | B23: Europe & Central Asia | C23: High income | D23: A simple multiplier is used to convert the national currencies of EMU members to euros. The following irrevocable euro conversion rate entered into force on January 1, 2026: 1 euro = 1.95583 Bulgarian Lev. Please note that historical data are not actual euros and are not comparable or suitable for aggregation across countries. | E23: Bulgaria
A24: BHR | B24: Middle East & North Africa | C24: High income | E24: Bahrain
A25: BHS | B25: Latin America & Caribbean | C25: High income | E25: Bahamas, The
A26: BIH | B26: Europe & Central Asia | C26: Upper middle income | E26: Bosnia and Herzegovina
A27: BLR | B27: Europe & Central Asia | C27: Upper middle income | D27: Data before 2015 were adjusted to reflect the new denomination effective from July 1, 2016 (BYN), a decrease of 10,000 times (1 BYN = 10,000 BYR) | E27: Belarus
A28: BLZ | B28: Latin America & Caribbean | C28: Upper middle income | E28: Belize
A29: BMU | B29: North America | C29: High income | E29: Bermuda
A30: BOL | B30: Latin America & Caribbean | C30: Lower middle income | E30: Bolivia
A31: BRA | B31: Latin America & Caribbean | C31: Upper middle income | E31: Brazil
A32: BRB | B32: Latin America & Caribbean | C32: High income | E32: Barbados
A33: BRN | B33: East Asia & Pacific | C33: High income | E33: Brunei Darussalam
A34: BTN | B34: South Asia | C34: Lower middle income | E34: Bhutan
A35: BWA | B35: Sub-Saharan Africa | C35: Upper middle income | E35: Botswana
A36: CAF | B36: Sub-Saharan Africa | C36: Low income | E36: Central African Republic
A37: CAN | B37: North America | C37: High income | D37: Fiscal year end: March 31; reporting period for national accounts data: CY. | E37: Canada
A38: CEB | D38: Central Europe and the Baltics aggregate. | E38: Central Europe and the Baltics
A39: CHE | B39: Europe & Central Asia | C39: High income | E39: Switzerland
A40: CHI | B40: Europe & Central Asia | C40: High income | E40: Channel Islands
...

Sheet Metadata - Indicators
A1: INDICATOR_CODE | B1: INDICATOR_NAME | C1: SOURCE_NOTE | D1: SOURCE_ORGANIZATION
A2: IT.NET.USER.ZS | B2: Individuals using the Internet (% of population) | C2: Internet users are individuals who have used the Internet (from any location) in the last 3 months. The Internet can be used via a computer, mobile phone, personal digital assistant, games machine, digital TV etc. | D2: World Telecommunication/ICT Indicators Database, International Telecommunication Union (ITU), uri: https://datahub.itu.int/

Sheet WB_CLEAN
A1: Country Name | B1: Country Code | C1: Region | D1: Internet Use (%) | E1: Include?
A2: Aruba | B2: ABW | C2: =_xlfn.XLOOKUP(B2,'Metadata - Countries'!A:A,'Metadata - Countries'!B:B,"Not found") -> Latin America & Caribbean | E2: =IF(AND(C2<>"",C2<>0,D2<>""),"Include","Exclude") -> Exclude
A3: Africa Eastern and Southern | B3: AFE | C3: =_xlfn.XLOOKUP(B3,'Metadata - Countries'!A:A,'Metadata - Countries'!B:B,"Not found") -> 0 | D3: 21.6 | E3: =IF(AND(C3<>"",C3<>0,D3<>""),"Include","Exclude") -> Exclude
A4: Afghanistan | B4: AFG | C4: =_xlfn.XLOOKUP(B4,'Metadata - Countries'!A:A,'Metadata - Countries'!B:B,"Not found") -> Middle East & North Africa | D4: 17.6 | E4: =IF(AND(C4<>"",C4<>0,D4<>""),"Include","Exclude") -> Include
A5: Africa Western and Central | B5: AFW | C5: =_xlfn.XLOOKUP(B5,'Metadata - Countries'!A:A,'Metadata - Countries'!B:B,"Not found") -> 0 | D5: 28.5 | E5: =IF(AND(C5<>"",C5<>0,D5<>""),"Include","Exclude") -> Exclude
A6: Angola | B6: AGO | C6: =_xlfn.XLOOKUP(B6,'Metadata - Countries'!A:A,'Metadata - Countries'!B:B,"Not found") -> Sub-Saharan Africa | D6: 32.129398 | E6: =IF(AND(C6<>"",C6<>0,D6<>""),"Include","Exclude") -> Include
A7: Albania | B7: ALB | C7: =_xlfn.XLOOKUP(B7,'Metadata - Countries'!A:A,'Metadata - Countries'!B:B,"Not found") -> Europe & Central Asia | D7: 68.550391 | E7: =IF(AND(C7<>"",C7<>0,D7<>""),"Include","Exclude") -> Include
A8: Andorra | B8: AND | C8: =_xlfn.XLOOKUP(B8,'Metadata - Countries'!A:A,'Metadata - Countries'!B:B,"Not found") -> Europe & Central Asia | D8: 90.718697 | E8: =IF(AND(C8<>"",C8<>0,D8<>""),"Include","Exclude") -> Include
A9: Arab World | B9: ARB | C9: =_xlfn.XLOOKUP(B9,'Metadata - Countries'!A:A,'Metadata - Countries'!B:B,"Not found") -> 0 | E9: =IF(AND(C9<>"",C9<>0,D9<>""),"Include","Exclude") -> Exclude
A10: United Arab Emirates | B10: ARE | C10: =_xlfn.XLOOKUP(B10,'Metadata - Countries'!A:A,'Metadata - Countries'!B:B,"Not found") -> Middle East & North Africa | D10: 99.149998 | E10: =IF(AND(C10<>"",C10<>0,D10<>""),"Include","Exclude") -> Include
A11: Argentina | B11: ARG | C11: =_xlfn.XLOOKUP(B11,'Metadata - Countries'!A:A,'Metadata - Countries'!B:B,"Not found") -> Latin America & Caribbean | D11: 79.946952 | E11: =IF(AND(C11<>"",C11<>0,D11<>""),"Include","Exclude") -> Include
A12: Armenia | B12: ARM | C12: =_xlfn.XLOOKUP(B12,'Metadata - Countries'!A:A,'Metadata - Countries'!B:B,"Not found") -> Europe & Central Asia | D12: 66.54395 | E12: =IF(AND(C12<>"",C12<>0,D12<>""),"Include","Exclude") -> Include
A13: American Samoa | B13: ASM | C13: =_xlfn.XLOOKUP(B13,'Metadata - Countries'!A:A,'Metadata - Countries'!B:B,"Not found") -> East Asia & Pacific | E13: =IF(AND(C13<>"",C13<>0,D13<>""),"Include","Exclude") -> Exclude
A14: Antigua and Barbuda | B14: ATG | C14: =_xlfn.XLOOKUP(B14,'Metadata - Countries'!A:A,'Metadata - Countries'!B:B,"Not found") -> Latin America & Caribbean | D14: 71.092598 | E14: =IF(AND(C14<>"",C14<>0,D14<>""),"Include","Exclude") -> Include
A15: Australia | B15: AUS | C15: =_xlfn.XLOOKUP(B15,'Metadata - Countries'!A:A,'Metadata - Countries'!B:B,"Not found") -> East Asia & Pacific | D15: 93.609901 | E15: =IF(AND(C15<>"",C15<>0,D15<>""),"Include","Exclude") -> Include
A16: Austria | B16: AUT | C16: =_xlfn.XLOOKUP(B16,'Metadata - Countries'!A:A,'Metadata - Countries'!B:B,"Not found") -> Europe & Central Asia | D16: 87.752205 | E16: =IF(AND(C16<>"",C16<>0,D16<>""),"Include","Exclude") -> Include
A17: Azerbaijan | B17: AZE | C17: =_xlfn.XLOOKUP(B17,'Metadata - Countries'!A:A,'Metadata - Countries'!B:B,"Not found") -> Europe & Central Asia | D17: 81.099999 | E17: =IF(AND(C17<>"",C17<>0,D17<>""),"Include","Exclude") -> Include
A18: Burundi | B18: BDI | C18: =_xlfn.XLOOKUP(B18,'Metadata - Countries'!A:A,'Metadata - Countries'!B:B,"Not found") -> Sub-Saharan Africa | D18: 6.0721998 | E18: =IF(AND(C18<>"",C18<>0,D18<>""),"Include","Exclude") -> Include
A19: Belgium | B19: BEL | C19: =_xlfn.XLOOKUP(B19,'Metadata - Countries'!A:A,'Metadata - Countries'!B:B,"Not found") -> Europe & Central Asia | D19: 90.275428 | E19: =IF(AND(C19<>"",C19<>0,D19<>""),"Include","Exclude") -> Include
A20: Benin | B20: BEN | C20: =_xlfn.XLOOKUP(B20,'Metadata - Countries'!A:A,'Metadata - Countries'!B:B,"Not found") -> Sub-Saharan Africa | D20: 20.500999 | E20: =IF(AND(C20<>"",C20<>0,D20<>""),"Include","Exclude") -> Include
A21: Burkina Faso | B21: BFA | C21: =_xlfn.XLOOKUP(B21,'Metadata - Countries'!A:A,'Metadata - Countries'!B:B,"Not found") -> Sub-Saharan Africa | D21: 9.271806 | E21: =IF(AND(C21<>"",C21<>0,D21<>""),"Include","Exclude") -> Include
A22: Bangladesh | B22: BGD | C22: =_xlfn.XLOOKUP(B22,'Metadata - Countries'!A:A,'Metadata - Countries'!B:B,"Not found") -> South Asia | D22: 30.383101 | E22: =IF(AND(C22<>"",C22<>0,D22<>""),"Include","Exclude") -> Include
A23: Bulgaria | B23: BGR | C23: =_xlfn.XLOOKUP(B23,'Metadata - Countries'!A:A,'Metadata - Countries'!B:B,"Not found") -> Europe & Central Asia | D23: 67.946981 | E23: =IF(AND(C23<>"",C23<>0,D23<>""),"Include","Exclude") -> Include
A24: Bahrain | B24: BHR | C24: =_xlfn.XLOOKUP(B24,'Metadata - Countries'!A:A,'Metadata - Countries'!B:B,"Not found") -> Middle East & North Africa | D24: 99.701504 | E24: =IF(AND(C24<>"",C24<>0,D24<>""),"Include","Exclude") -> Include
A25: Bahamas, The | B25: BHS | C25: =_xlfn.XLOOKUP(B25,'Metadata - Countries'!A:A,'Metadata - Countries'!B:B,"Not found") -> Latin America & Caribbean | D25: 90.693298 | E25: =IF(AND(C25<>"",C25<>0,D25<>""),"Include","Exclude") -> Include
... A28: Belize | B28: BLZ | C28: =_xlfn.XLOOKUP(B28,'Metadata - Countries'!A:A,'Metadata - Countries'!B:B,"Not found") -> Latin America & Caribbean | D28: 58.765202 | E28: =IF(AND(C28<>"",C28<>0,D28<>""),"Include","Exclude") -> Include
A29: Bermuda | B29: BMU | C29: =_xlfn.XLOOKUP(B29,'Metadata - Countries'!A:A,'Metadata - Countries'!B:B,"Not found") -> North America | E29: =IF(AND(C29<>"",C29<>0,D29<>""),"Include","Exclude") -> Exclude
A30: Bolivia | B30: BOL | C30: =_xlfn.XLOOKUP(B30,'Metadata - Countries'!A:A,'Metadata - Countries'!B:B,"Not found") -> Latin America & Caribbean | D30: 47.474819 | E30: =IF(AND(C30<>"",C30<>0,D30<>""),"Include","Exclude") -> Include
A31: Brazil | B31: BRA | C31: =_xlfn.XLOOKUP(B31,'Metadata - Countries'!A:A,'Metadata - Countries'!B:B,"Not found") -> Latin America & Caribbean | D31: 73.91244 | E31: =IF(AND(C31<>"",C31<>0,D31<>""),"Include","Exclude") -> Include
A32: Barbados | B32: BRB | C32: =_xlfn.XLOOKUP(B32,'Metadata - Countries'!A:A,'Metadata - Countries'!B:B,"Not found") -> Latin America & Caribbean | D32: 70.307098 | E32: =IF(AND(C32<>"",C32<>0,D32<>""),"Include","Exclude") -> Include
A33: Brunei Darussalam | B33: BRN | C33: =_xlfn.XLOOKUP(B33,'Metadata - Countries'!A:A,'Metadata - Countries'!B:B,"Not found") -> East Asia & Pacific | D33: 95 | E33: =IF(AND(C33<>"",C33<>0,D33<>""),"Include","Exclude") -> Include
A34: Bhutan | B34: BTN | C34: =_xlfn.XLOOKUP(B34,'Metadata - Countries'!A:A,'Metadata - Countries'!B:B,"Not found") -> South Asia | D34: 74.179398 | E34: =IF(AND(C34<>"",C34<>0,D34<>""),"Include","Exclude") -> Include
A35: Botswana | B35: BWA | C35: =_xlfn.XLOOKUP(B35,'Metadata - Countries'!A:A,'Metadata - Countries'!B:B,"Not found") -> Sub-Saharan Africa | D35: 48.8228 | E35: =IF(AND(C35<>"",C35<>0,D35<>""),"Include","Exclude") -> Include
A36: Central African Republic | B36: CAF | C36: =_xlfn.XLOOKUP(B36,'Metadata - Countries'!A:A,'Metadata - Countries'!B:B,"Not found") -> Sub-Saharan Africa | D36: 7.5092001 | E36: =IF(AND(C36<>"",C36<>0,D36<>""),"Include","Exclude") -> Include
A37: Canada | B37: CAN | C37: =_xlfn.XLOOKUP(B37,'Metadata - Countries'!A:A,'Metadata - Countries'!B:B,"Not found") -> North America | D37: 91.912903 | E37: =IF(AND(C37<>"",C37<>0,D37<>""),"Include","Exclude") -> Include
A38: Central Europe and the Baltics | B38: CEB | C38: =_xlfn.XLOOKUP(B38,'Metadata - Countries'!A:A,'Metadata - Countries'!B:B,"Not found") -> 0 | E38: =IF(AND(C38<>"",C38<>0,D38<>""),"Include","Exclude") -> Exclude
A39: Switzerland | B39: CHE | C39: =_xlfn.XLOOKUP(B39,'Metadata - Countries'!A:A,'Metadata - Countries'!B:B,"Not found") -> Europe & Central Asia | D39: 93.146087 | E39: =IF(AND(C39<>"",C39<>0,D39<>""),"Include","Exclude") -> Include
A40: Channel Islands | B40: CHI | C40: =_xlfn.XLOOKUP(B40,'Metadata - Countries'!A:A,'Metadata - Countries'!B:B,"Not found") -> Europe & Central Asia | E40: =IF(AND(C40<>"",C40<>0,D40<>""),"Include","Exclude") -> Exclude
A41: Chile | B41: CHL | C41: =_xlfn.XLOOKUP(B41,'Metadata - Countries'!A:A,'Metadata - Countries'!B:B,"Not found") -> Latin America & Caribbean | D41: 85.017601 | E41: =IF(AND(C41<>"",C41<>0,D41<>""),"Include","Exclude") -> Include
A42: China | B42: CHN | C42: =_xlfn.XLOOKUP(B42,'Metadata - Countries'!A:A,'Metadata - Countries'!B:B,"Not found") -> East Asia & Pacific | D42: 64.080881 | E42: =IF(AND(C42<>"",C42<>0,D42<>""),"Include","Exclude") -> Include
...

Sheet WB_ANALYSIS_DATA
A1: Country Name | B1: Country Code | C1: Region | D1: Internet Use (%) | F1: WB_ANALYSIS_DATA — Documentation
A2: Afghanistan | B2: AFG | C2: =_xlfn.XLOOKUP(B2,'Metadata - Countries'!A:A,'Metadata - Countries'!B:B,"Not found") -> Middle East & North Africa | D2: 17.6 | F2: Purpose: Prepare a country-level dataset for comparing Internet use across World Bank geographic regions in 2019.
A3: Angola | B3: AGO | C3: =_xlfn.XLOOKUP(B3,'Metadata - Countries'!A:A,'Metadata - Countries'!B:B,"Not found") -> Sub-Saharan Africa | D3: 32.129398 | F3: Source: World Bank, World Development Indicators
A4: Albania | B4: ALB | C4: =_xlfn.XLOOKUP(B4,'Metadata - Countries'!A:A,'Metadata - Countries'!B:B,"Not found") -> Europe & Central Asia | D4: 68.550391 | F4: Indicator code:
A5: Andorra | B5: AND | C5: =_xlfn.XLOOKUP(B5,'Metadata - Countries'!A:A,'Metadata - Countries'!B:B,"Not found") -> Europe & Central Asia | D5: 90.718697 | F5: IT.NET.USER.ZS
A6: United Arab Emirates | B6: ARE | C6: =_xlfn.XLOOKUP(B6,'Metadata - Countries'!A:A,'Metadata - Countries'!B:B,"Not found") -> Middle East & North Africa | D6: 99.149998
A7: Argentina | B7: ARG | C7: =_xlfn.XLOOKUP(B7,'Metadata - Countries'!A:A,'Metadata - Countries'!B:B,"Not found") -> Latin America & Caribbean | D7: 79.946952 | F7: Indicator: Individuals using the Internet (% of population)
A8: Armenia | B8: ARM | C8: =_xlfn.XLOOKUP(B8,'Metadata - Countries'!A:A,'Metadata - Countries'!B:B,"Not found") -> Europe & Central Asia | D8: 66.54395 | F8: Reference year: 2019
A9: Antigua and Barbuda | B9: ATG | C9: =_xlfn.XLOOKUP(B9,'Metadata - Countries'!A:A,'Metadata - Countries'!B:B,"Not found") -> Latin America & Caribbean | D9: 71.092598 | F9: Variables
A10: Australia | B10: AUS | C10: =_xlfn.XLOOKUP(B10,'Metadata - Countries'!A:A,'Metadata - Countries'!B:B,"Not found") -> East Asia & Pacific | D10: 93.609901 | F10: Country Name
A11: Austria | B11: AUT | C11: =_xlfn.XLOOKUP(B11,'Metadata - Countries'!A:A,'Metadata - Countries'!B:B,"Not found") -> Europe & Central Asia | D11: 87.752205 | F11: : Economy name as provided by the source.
A12: Azerbaijan | B12: AZE | C12: =_xlfn.XLOOKUP(B12,'Metadata - Countries'!A:A,'Metadata - Countries'!B:B,"Not found") -> Europe & Central Asia | D12: 81.099999 | F12: Country Code
A13: Burundi | B13: BDI | C13: =_xlfn.XLOOKUP(B13,'Metadata - Countries'!A:A,'Metadata - Countries'!B:B,"Not found") -> Sub-Saharan Africa | D13: 6.0721998 | F13: : World Bank economy code.
A14: Belgium | B14: BEL | C14: =_xlfn.XLOOKUP(B14,'Metadata - Countries'!A:A,'Metadata - Countries'!B:B,"Not found") -> Europe & Central Asia | D14: 90.275428 | F14: Region
A15: Benin | B15: BEN | C15: =_xlfn.XLOOKUP(B15,'Metadata - Countries'!A:A,'Metadata - Countries'!B:B,"Not found") -> Sub-Saharan Africa | D15: 20.500999 | F15: : Geographic region obtained from the country metadata.
A16: Burkina Faso | B16: BFA | C16: =_xlfn.XLOOKUP(B16,'Metadata - Countries'!A:A,'Metadata - Countries'!B:B,"Not found") -> Sub-Saharan Africa | D16: 9.271806 | F16: Internet Use (%)
A17: Bangladesh | B17: BGD | C17: =_xlfn.XLOOKUP(B17,'Metadata - Countries'!A:A,'Metadata - Countries'!B:B,"Not found") -> South Asia | D17: 30.383101 | F17: : Indicator value for 2019.
A18: Bulgaria | B18: BGR | C18: =_xlfn.XLOOKUP(B18,'Metadata - Countries'!A:A,'Metadata - Countries'!B:B,"Not found") -> Europe & Central Asia | D18: 67.946981 | F18: Inclusion rules
A19: Bahrain | B19: BHR | C19: =_xlfn.XLOOKUP(B19,'Metadata - Countries'!A:A,'Metadata - Countries'!B:B,"Not found") -> Middle East & North Africa | D19: 99.701504 | F19: 1 | G19: Include only individual economies with a verified geographic region.
A20: Bahamas, The | B20: BHS | C20: =_xlfn.XLOOKUP(B20,'Metadata - Countries'!A:A,'Metadata - Countries'!B:B,"Not found") -> Latin America & Caribbean | D20: 90.693298 | F20: 2 | G20: Include only valid numeric Internet-use observations for 2019.
A21: Bosnia and Herzegovina | B21: BIH | C21: =_xlfn.XLOOKUP(B21,'Metadata - Countries'!A:A,'Metadata - Countries'!B:B,"Not found") -> Europe & Central Asia | D21: 69.946348 | F21: 3 | G21: Exclude regional and income-group aggregates from country-level regional averages.
A22: Belarus | B22: BLR | C22: =_xlfn.XLOOKUP(B22,'Metadata - Countries'!A:A,'Metadata - Countries'!B:B,"Not found") -> Europe & Central Asia | D22: 82.789152 | F22: 4 | G22: Retain missing or unresolved observations in the source/cleaning worksheet for transparency, but exclude them from the analysis dataset.
A23: Belize | B23: BLZ | C23: =_xlfn.XLOOKUP(B23,'Metadata - Countries'!A:A,'Metadata - Countries'!B:B,"Not found") -> Latin America & Caribbean | D23: 58.765202 | F23: 5 | G23: Do not replace missing values with zero.
A24: Bolivia | B24: BOL | C24: =_xlfn.XLOOKUP(B24,'Metadata - Countries'!A:A,'Metadata - Countries'!B:B,"Not found") -> Latin America & Caribbean | D24: 47.474819 | F24: Analytical method
A25: Brazil | B25: BRA | C25: =_xlfn.XLOOKUP(B25,'Metadata - Countries'!A:A,'Metadata - Countries'!B:B,"Not found") -> Latin America & Caribbean | D25: 73.91244 | F25: Calculate the unweighted mean of available country-level Internet-use percentages by geographic region. Use minimum, maximum, and range to examine the spread of country observations.
A26: Barbados | B26: BRB | C26: =_xlfn.XLOOKUP(B26,'Metadata - Countries'!A:A,'Metadata - Countries'!B:B,"Not found") -> Latin America & Caribbean | D26: 70.307098 | F26: Limitations
A27: Brunei Darussalam | B27: BRN | C27: =_xlfn.XLOOKUP(B27,'Metadata - Countries'!A:A,'Metadata - Countries'!B:B,"Not found") -> East Asia & Pacific | D27: 95 | F27: The analysis is descriptive. Country-level averages are not population-weighted regional rates, and differences between regions do not establish causal relationships. Results depend on the coverage and completeness of the 2019 observations.
A28: Bhutan | B28: BTN | C28: =_xlfn.XLOOKUP(B28,'Metadata - Countries'!A:A,'Metadata - Countries'!B:B,"Not found") -> South Asia | D28: 74.179398 | F28: Reproducibility
A29: Botswana | B29: BWA | C29: =_xlfn.XLOOKUP(B29,'Metadata - Countries'!A:A,'Metadata - Countries'!B:B,"Not found") -> Sub-Saharan Africa | D29: 48.8228 | F29: Record the final number of included economies, the date the source data were downloaded, and any unresolved region classifications before publishing the results.
A30: Central African Republic | B30: CAF | C30: =_xlfn.XLOOKUP(B30,'Metadata - Countries'!A:A,'Metadata - Countries'!B:B,"Not found") -> Sub-Saharan Africa | D30: 7.5092001
A31: Canada | B31: CAN | C31: =_xlfn.XLOOKUP(B31,'Metadata - Countries'!A:A,'Metadata - Countries'!B:B,"Not found") -> North America | D31: 91.912903
A32: Switzerland | B32: CHE | C32: =_xlfn.XLOOKUP(B32,'Metadata - Countries'!A:A,'Metadata - Countries'!B:B,"Not found") -> Europe & Central Asia | D32: 93.146087
A33: Chile | B33: CHL | C33: =_xlfn.XLOOKUP(B33,'Metadata - Countries'!A:A,'Metadata - Countries'!B:B,"Not found") -> Latin America & Caribbean | D33: 85.017601
A34: China | B34: CHN | C34: =_xlfn.XLOOKUP(B34,'Metadata - Countries'!A:A,'Metadata - Countries'!B:B,"Not found") -> East Asia & Pacific | D34: 64.080881
A35: Cote d'Ivoire | B35: CIV | C35: =_xlfn.XLOOKUP(B35,'Metadata - Countries'!A:A,'Metadata - Countries'!B:B,"Not found") -> Sub-Saharan Africa | D35: 36.288955
A36: Cameroon | B36: CMR | C36: =_xlfn.XLOOKUP(B36,'Metadata - Countries'!A:A,'Metadata - Countries'!B:B,"Not found") -> Sub-Saharan Africa | D36: 36.5392
A37: Congo, Dem. Rep. | B37: COD | C37: =_xlfn.XLOOKUP(B37,'Metadata - Countries'!A:A,'Metadata - Countries'!B:B,"Not found") -> Sub-Saharan Africa | D37: 13.0297
A38: Congo, Rep. | B38: COG | C38: =_xlfn.XLOOKUP(B38,'Metadata - Countries'!A:A,'Metadata - Countries'!B:B,"Not found") -> Sub-Saharan Africa | D38: 16.1164
A39: Colombia | B39: COL | C39: =_xlfn.XLOOKUP(B39,'Metadata - Countries'!A:A,'Metadata - Countries'!B:B,"Not found") -> Latin America & Caribbean | D39: 65.006901
A40: Comoros | B40: COM | C40: =_xlfn.XLOOKUP(B40,'Metadata - Countries'!A:A,'Metadata - Countries'!B:B,"Not found") -> Sub-Saharan Africa | D40: 16.383801
...

Sheet WB_PIVOT
A2: Research Question: What was the average country-level Internet-use percentage in each World Bank geographic region in 2019?
A5: Region | B5: Average of Internet Use (%) | C5: Count of Country Code
A6: East Asia & Pacific | B6: 62.18299 | C6: 27
A7: Europe & Central Asia | B7: 81.040703 | C7: 51
A8: Latin America & Caribbean | B8: 64.770252 | C8: 34
A9: Middle East & North Africa | B9: 70.068157 | C9: 22
A10: North America | B10: 90.671594 | C10: 2
A11: South Asia | B11: 46.152201 | C11: 6
A12: Sub-Saharan Africa | B12: 27.190369 | C12: 47
A13: Grand Total | B13: 59.745547 | C13: 189
A16: Interpretation
A17: Finding: In 2019, North America had the highest average Internet-use percentage (90.68%), while Sub-Saharan Africa had the lowest at 27.2%.
A18: Interpretation: Internet use differed across geographic regions. Differences may reflect infrastructure, affordability, income, and access, but this descriptive analysis cannot identify the causes.
A20: Limitation: The figures represent an unweighted average of available country-level percentages, not the population-weighted Internet-use rate for each region. Countries with missing data are excluded.
A23: Research Question 2: Which regions show the greatest variation in Internet use across countries?
A25: Region | B25: Min of Internet Use (%)2 | C25: Max of Internet Use (%)3 | D25: Average of Internet Use (%)
A26: East Asia & Pacific | B26: 13.6242 | C26: 96.157579 | D26: 62.18299
A27: Europe & Central Asia | B27: 22.6863 | C27: 99.504941 | D27: 81.040703
A28: Latin America & Caribbean | B28: 35.764099 | C28: 90.693298 | D28: 64.770252
A29: Middle East & North Africa | B29: 17.070902 | C29: 99.701504 | D29: 70.068157
A30: North America | B30: 89.430285 | C30: 91.912903 | D30: 90.671594
A31: South Asia | B31: 29.5235 | C31: 77.469704 | D31: 46.152201
A32: Sub-Saharan Africa | B32: 2.7314 | C32: 76.634201 | D32: 27.190369
A33: Grand Total | B33: 2.7314 | C33: 99.701504 | D33: 59.745547
A36: Region | B36: Min of Internet Use (%)2 | C36: Max of Internet Use (%)3 | D36: Range
A37: East Asia & Pacific | B37: 13.6242 | C37: 96.157579 | D37: =C37-B37 -> 82.533379
A38: Europe & Central Asia | B38: 22.6863 | C38: 99.504941 | D38: =C38-B38 -> 76.818641
A39: Latin America & Caribbean | B39: 35.764099 | C39: 90.693298 | D39: =C39-B39 -> 54.929199
A40: Middle East & North Africa | B40: 17.070902 | C40: 99.701504 | D40: =C40-B40 -> 82.630603
A41: North America | B41: 89.430285 | C41: 91.912903 | D41: =C41-B41 -> 2.482618
A42: South Asia | B42: 29.5235 | C42: 77.469704 | D42: =C42-B42 -> 47.946203
A43: Sub-Saharan Africa | B43: 2.7314 | C43: 76.634201 | D43: =C43-B43 -> 73.902801
A45: Interpretation
A46: Finding: In 2019, Middle East & North Africa had the largest range in country-level Internet use, at 82.63 percentage points, while North America had the smallest range, at 2.49 percentage points.
A48: Interpretation: The results suggest that the gap between the highest- and lowest-Internet-use countries differed across regions. A larger range indicates greater separation between the two extremes, while a smaller range indicates that the extremes were closer together.
A51: Limitation: The range uses only the minimum and maximum values and ignores all countries between them. It can be influenced by extreme observations and does not establish the causes of regional differences. Missing country observations may also affect the calculated range.
A53: Research note: These are descriptive results for 2019. Avoid claiming that a region has greater overall inequality based on the range alone; standard deviation or interquartile range would provide additional information about the distribution.
A56: Research Question 3: Which countries have the highest and lowest Internet use within each region?
A58: Region | B58: Country Name | C58: Average of Internet Use (%)
A59: South Asia | B59: Maldives | C59: 77.469704
...
